2023-07-12 11:39:03.699 | INFO     | common.utils:__api_log:32 - 请求方式：post
2023-07-12 11:39:03.699 | INFO     | common.utils:__api_log:33 - 请求地址：http://polygon-mumbai.testnet.863863.xyz/v1/rpc/fb90c5a628b19148d4f01da617219548c978cb6e
2023-07-12 11:39:03.699 | INFO     | common.utils:__api_log:34 - 请求头：{'Content-Type': 'application/json'}
2023-07-12 11:39:03.700 | INFO     | common.utils:__api_log:35 - 请求参数：None
2023-07-12 11:39:03.700 | INFO     | common.utils:__api_log:36 - 请求体：{'jsonrpc': '2.0', 'method': 'eth_chainId', 'params': [], 'id': 1}

2023-07-12 11:39:04.286 | ERROR    | common.utils:send_http:23 - 发送请求失败，请求参数为：{'url': 'http://polygon-mumbai.testnet.863863.xyz/v1/rpc/fb90c5a628b19148d4f01da617219548c978cb6e', 'method': 'post', 'headers': {'Content-Type': 'application/json'}, 'json': {'jsonrpc': '2.0', 'method': 'eth_chainId', 'params': [], 'id': 1}}
2023-07-12 11:39:04.286 | ERROR    | common.utils:send_http:24 - 发生的错误为：('Connection aborted.', RemoteDisconnected('Remote end closed connection without response'))
Traceback (most recent call last):

  File "C:\Users\Wyc\AppData\Roaming\Python\Python311\site-packages\urllib3\connectionpool.py", line 703, in urlopen
    httplib_response = self._make_request(
                       │    └ <function HTTPConnectionPool._make_request at 0x000001D4FCD5B380>
                       └ <urllib3.connectionpool.HTTPConnectionPool object at 0x000001D4FB8A1BD0>
  File "C:\Users\Wyc\AppData\Roaming\Python\Python311\site-packages\urllib3\connectionpool.py", line 449, in _make_request
    six.raise_from(e, None)
    │   └ <function raise_from at 0x000001D4FB79B740>
    └ <module 'urllib3.packages.six' from 'C:\\Users\\Wyc\\AppData\\Roaming\\Python\\Python311\\site-packages\\urllib3\\packages\\s...
  File "<string>", line 3, in raise_from
  File "C:\Users\Wyc\AppData\Roaming\Python\Python311\site-packages\urllib3\connectionpool.py", line 444, in _make_request
    httplib_response = conn.getresponse()
                       │    └ <function HTTPConnection.getresponse at 0x000001D4FB7F6340>
                       └ <urllib3.connection.HTTPConnection object at 0x000001D4FB8A2990>
  File "C:\Program Files\Python\Lib\http\client.py", line 1375, in getresponse
    response.begin()
    │        └ <function HTTPResponse.begin at 0x000001D4FB7F4400>
    └ <http.client.HTTPResponse object at 0x000001D4FB8A6290>
  File "C:\Program Files\Python\Lib\http\client.py", line 318, in begin
    version, status, reason = self._read_status()
                              │    └ <function HTTPResponse._read_status at 0x000001D4FB7F4360>
                              └ <http.client.HTTPResponse object at 0x000001D4FB8A6290>
  File "C:\Program Files\Python\Lib\http\client.py", line 287, in _read_status
    raise RemoteDisconnected("Remote end closed connection without"
          └ <class 'http.client.RemoteDisconnected'>

http.client.RemoteDisconnected: Remote end closed connection without response


During handling of the above exception, another exception occurred:


Traceback (most recent call last):

  File "C:\Users\Wyc\AppData\Roaming\Python\Python311\site-packages\requests\adapters.py", line 487, in send
    resp = conn.urlopen(
           │    └ <function HTTPConnectionPool.urlopen at 0x000001D4FCD5B600>
           └ <urllib3.connectionpool.HTTPConnectionPool object at 0x000001D4FB8A1BD0>
  File "C:\Users\Wyc\AppData\Roaming\Python\Python311\site-packages\urllib3\connectionpool.py", line 787, in urlopen
    retries = retries.increment(
              │       └ <function Retry.increment at 0x000001D4FB813600>
              └ Retry(total=0, connect=None, read=False, redirect=None, status=None)
  File "C:\Users\Wyc\AppData\Roaming\Python\Python311\site-packages\urllib3\util\retry.py", line 550, in increment
    raise six.reraise(type(error), error, _stacktrace)
          │   │            │       │      └ <traceback object at 0x000001D4FB8A2180>
          │   │            │       └ ProtocolError('Connection aborted.', RemoteDisconnected('Remote end closed connection without response'))
          │   │            └ ProtocolError('Connection aborted.', RemoteDisconnected('Remote end closed connection without response'))
          │   └ <function reraise at 0x000001D4FB79B600>
          └ <module 'urllib3.packages.six' from 'C:\\Users\\Wyc\\AppData\\Roaming\\Python\\Python311\\site-packages\\urllib3\\packages\\s...
  File "C:\Users\Wyc\AppData\Roaming\Python\Python311\site-packages\urllib3\packages\six.py", line 769, in reraise
    raise value.with_traceback(tb)
          │                    └ None
          └ None
  File "C:\Users\Wyc\AppData\Roaming\Python\Python311\site-packages\urllib3\connectionpool.py", line 703, in urlopen
    httplib_response = self._make_request(
                       │    └ <function HTTPConnectionPool._make_request at 0x000001D4FCD5B380>
                       └ <urllib3.connectionpool.HTTPConnectionPool object at 0x000001D4FB8A1BD0>
  File "C:\Users\Wyc\AppData\Roaming\Python\Python311\site-packages\urllib3\connectionpool.py", line 449, in _make_request
    six.raise_from(e, None)
    │   └ <function raise_from at 0x000001D4FB79B740>
    └ <module 'urllib3.packages.six' from 'C:\\Users\\Wyc\\AppData\\Roaming\\Python\\Python311\\site-packages\\urllib3\\packages\\s...
  File "<string>", line 3, in raise_from
  File "C:\Users\Wyc\AppData\Roaming\Python\Python311\site-packages\urllib3\connectionpool.py", line 444, in _make_request
    httplib_response = conn.getresponse()
                       │    └ <function HTTPConnection.getresponse at 0x000001D4FB7F6340>
                       └ <urllib3.connection.HTTPConnection object at 0x000001D4FB8A2990>
  File "C:\Program Files\Python\Lib\http\client.py", line 1375, in getresponse
    response.begin()
    │        └ <function HTTPResponse.begin at 0x000001D4FB7F4400>
    └ <http.client.HTTPResponse object at 0x000001D4FB8A6290>
  File "C:\Program Files\Python\Lib\http\client.py", line 318, in begin
    version, status, reason = self._read_status()
                              │    └ <function HTTPResponse._read_status at 0x000001D4FB7F4360>
                              └ <http.client.HTTPResponse object at 0x000001D4FB8A6290>
  File "C:\Program Files\Python\Lib\http\client.py", line 287, in _read_status
    raise RemoteDisconnected("Remote end closed connection without"
          └ <class 'http.client.RemoteDisconnected'>

urllib3.exceptions.ProtocolError: ('Connection aborted.', RemoteDisconnected('Remote end closed connection without response'))


During handling of the above exception, another exception occurred:


Traceback (most recent call last):

  File "D:\OneDrive\Work\BlockPi\test_jsonrpc\run.py", line 11, in <module>
    pytest.main(['-s', r"--alluredir=report/json", "--clean-alluredir"])
    │      └ <function main at 0x000001D4F74F5260>
    └ <module 'pytest' from 'C:\\Program Files\\Python\\Lib\\site-packages\\pytest\\__init__.py'>

  File "C:\Program Files\Python\Lib\site-packages\_pytest\config\__init__.py", line 166, in main
    ret: Union[ExitCode, int] = config.hook.pytest_cmdline_main(
         │     │                │      │    └ <_HookCaller 'pytest_cmdline_main'>
         │     │                │      └ <_pytest.config.compat.PathAwareHookProxy object at 0x000001D4F960E4D0>
         │     │                └ <_pytest.config.Config object at 0x000001D4F95FADD0>
         │     └ <enum 'ExitCode'>
         └ typing.Union
  File "C:\Program Files\Python\Lib\site-packages\pluggy\_hooks.py", line 265, in __call__
    return self._hookexec(self.name, self.get_hookimpls(), kwargs, firstresult)
           │    │         │    │     │    │                │       └ True
           │    │         │    │     │    │                └ {'config': <_pytest.config.Config object at 0x000001D4F95FADD0>}
           │    │         │    │     │    └ <function _HookCaller.get_hookimpls at 0x000001D4F71D09A0>
           │    │         │    │     └ <_HookCaller 'pytest_cmdline_main'>
           │    │         │    └ 'pytest_cmdline_main'
           │    │         └ <_HookCaller 'pytest_cmdline_main'>
           │    └ <bound method PluginManager._hookexec of <_pytest.config.PytestPluginManager object at 0x000001D4F95F9F10>>
           └ <_HookCaller 'pytest_cmdline_main'>
  File "C:\Program Files\Python\Lib\site-packages\pluggy\_manager.py", line 80, in _hookexec
    return self._inner_hookexec(hook_name, methods, kwargs, firstresult)
           │    │               │          │        │       └ True
           │    │               │          │        └ {'config': <_pytest.config.Config object at 0x000001D4F95FADD0>}
           │    │               │          └ [<HookImpl plugin_name='main', plugin=<module '_pytest.main' from 'C:\\Program Files\\Python\\Lib\\site-packages\\_pytest\\ma...
           │    │               └ 'pytest_cmdline_main'
           │    └ <function _multicall at 0x000001D4F71B3920>
           └ <_pytest.config.PytestPluginManager object at 0x000001D4F95F9F10>
  File "C:\Program Files\Python\Lib\site-packages\pluggy\_callers.py", line 39, in _multicall
    res = hook_impl.function(*args)
          │         │         └ [<_pytest.config.Config object at 0x000001D4F95FADD0>]
          │         └ <function pytest_cmdline_main at 0x000001D4F79A3560>
          └ <HookImpl plugin_name='main', plugin=<module '_pytest.main' from 'C:\\Program Files\\Python\\Lib\\site-packages\\_pytest\\mai...
  File "C:\Program Files\Python\Lib\site-packages\_pytest\main.py", line 316, in pytest_cmdline_main
    return wrap_session(config, _main)
           │            │       └ <function _main at 0x000001D4F79A34C0>
           │            └ <_pytest.config.Config object at 0x000001D4F95FADD0>
           └ <function wrap_session at 0x000001D4F79A3420>
  File "C:\Program Files\Python\Lib\site-packages\_pytest\main.py", line 269, in wrap_session
    session.exitstatus = doit(config, session) or 0
    │       │            │    │       └ <Session test_jsonrpc exitstatus=<ExitCode.OK: 0> testsfailed=0 testscollected=3>
    │       │            │    └ <_pytest.config.Config object at 0x000001D4F95FADD0>
    │       │            └ <function _main at 0x000001D4F79A34C0>
    │       └ <ExitCode.OK: 0>
    └ <Session test_jsonrpc exitstatus=<ExitCode.OK: 0> testsfailed=0 testscollected=3>
  File "C:\Program Files\Python\Lib\site-packages\_pytest\main.py", line 323, in _main
    config.hook.pytest_runtestloop(session=session)
    │      │    │                          └ <Session test_jsonrpc exitstatus=<ExitCode.OK: 0> testsfailed=0 testscollected=3>
    │      │    └ <_HookCaller 'pytest_runtestloop'>
    │      └ <_pytest.config.compat.PathAwareHookProxy object at 0x000001D4F960E4D0>
    └ <_pytest.config.Config object at 0x000001D4F95FADD0>
  File "C:\Program Files\Python\Lib\site-packages\pluggy\_hooks.py", line 265, in __call__
    return self._hookexec(self.name, self.get_hookimpls(), kwargs, firstresult)
           │    │         │    │     │    │                │       └ True
           │    │         │    │     │    │                └ {'session': <Session test_jsonrpc exitstatus=<ExitCode.OK: 0> testsfailed=0 testscollected=3>}
           │    │         │    │     │    └ <function _HookCaller.get_hookimpls at 0x000001D4F71D09A0>
           │    │         │    │     └ <_HookCaller 'pytest_runtestloop'>
           │    │         │    └ 'pytest_runtestloop'
           │    │         └ <_HookCaller 'pytest_runtestloop'>
           │    └ <bound method PluginManager._hookexec of <_pytest.config.PytestPluginManager object at 0x000001D4F95F9F10>>
           └ <_HookCaller 'pytest_runtestloop'>
  File "C:\Program Files\Python\Lib\site-packages\pluggy\_manager.py", line 80, in _hookexec
    return self._inner_hookexec(hook_name, methods, kwargs, firstresult)
           │    │               │          │        │       └ True
           │    │               │          │        └ {'session': <Session test_jsonrpc exitstatus=<ExitCode.OK: 0> testsfailed=0 testscollected=3>}
           │    │               │          └ [<HookImpl plugin_name='main', plugin=<module '_pytest.main' from 'C:\\Program Files\\Python\\Lib\\site-packages\\_pytest\\ma...
           │    │               └ 'pytest_runtestloop'
           │    └ <function _multicall at 0x000001D4F71B3920>
           └ <_pytest.config.PytestPluginManager object at 0x000001D4F95F9F10>
  File "C:\Program Files\Python\Lib\site-packages\pluggy\_callers.py", line 39, in _multicall
    res = hook_impl.function(*args)
          │         │         └ [<Session test_jsonrpc exitstatus=<ExitCode.OK: 0> testsfailed=0 testscollected=3>]
          │         └ <function pytest_runtestloop at 0x000001D4F79A36A0>
          └ <HookImpl plugin_name='main', plugin=<module '_pytest.main' from 'C:\\Program Files\\Python\\Lib\\site-packages\\_pytest\\mai...
  File "C:\Program Files\Python\Lib\site-packages\_pytest\main.py", line 348, in pytest_runtestloop
    item.config.hook.pytest_runtest_protocol(item=item, nextitem=nextitem)
    │    │                                        │              └ <Function test_eth_syncing[data0]>
    │    │                                        └ <Function test_eth_chainId[data0]>
    │    └ <member 'config' of 'Node' objects>
    └ <Function test_eth_chainId[data0]>
  File "C:\Program Files\Python\Lib\site-packages\pluggy\_hooks.py", line 265, in __call__
    return self._hookexec(self.name, self.get_hookimpls(), kwargs, firstresult)
           │    │         │    │     │    │                │       └ True
           │    │         │    │     │    │                └ {'item': <Function test_eth_chainId[data0]>, 'nextitem': <Function test_eth_syncing[data0]>}
           │    │         │    │     │    └ <function _HookCaller.get_hookimpls at 0x000001D4F71D09A0>
           │    │         │    │     └ <_HookCaller 'pytest_runtest_protocol'>
           │    │         │    └ 'pytest_runtest_protocol'
           │    │         └ <_HookCaller 'pytest_runtest_protocol'>
           │    └ <bound method PluginManager._hookexec of <_pytest.config.PytestPluginManager object at 0x000001D4F95F9F10>>
           └ <_HookCaller 'pytest_runtest_protocol'>
  File "C:\Program Files\Python\Lib\site-packages\pluggy\_manager.py", line 80, in _hookexec
    return self._inner_hookexec(hook_name, methods, kwargs, firstresult)
           │    │               │          │        │       └ True
           │    │               │          │        └ {'item': <Function test_eth_chainId[data0]>, 'nextitem': <Function test_eth_syncing[data0]>}
           │    │               │          └ [<HookImpl plugin_name='runner', plugin=<module '_pytest.runner' from 'C:\\Program Files\\Python\\Lib\\site-packages\\_pytest...
           │    │               └ 'pytest_runtest_protocol'
           │    └ <function _multicall at 0x000001D4F71B3920>
           └ <_pytest.config.PytestPluginManager object at 0x000001D4F95F9F10>
  File "C:\Program Files\Python\Lib\site-packages\pluggy\_callers.py", line 39, in _multicall
    res = hook_impl.function(*args)
          │         │         └ [<Function test_eth_chainId[data0]>, <Function test_eth_syncing[data0]>]
          │         └ <function pytest_runtest_protocol at 0x000001D4F79A2520>
          └ <HookImpl plugin_name='runner', plugin=<module '_pytest.runner' from 'C:\\Program Files\\Python\\Lib\\site-packages\\_pytest\...
  File "C:\Program Files\Python\Lib\site-packages\_pytest\runner.py", line 114, in pytest_runtest_protocol
    runtestprotocol(item, nextitem=nextitem)
    │               │              └ <Function test_eth_syncing[data0]>
    │               └ <Function test_eth_chainId[data0]>
    └ <function runtestprotocol at 0x000001D4F79A25C0>
  File "C:\Program Files\Python\Lib\site-packages\_pytest\runner.py", line 133, in runtestprotocol
    reports.append(call_and_report(item, "call", log))
    │       │      │               │             └ True
    │       │      │               └ <Function test_eth_chainId[data0]>
    │       │      └ <function call_and_report at 0x000001D4F79A2980>
    │       └ <method 'append' of 'list' objects>
    └ [<TestReport 'testcases/test_jsonrpc.py::TestJsonrpc::test_eth_chainId[data0]' when='setup' outcome='passed'>]
  File "C:\Program Files\Python\Lib\site-packages\_pytest\runner.py", line 222, in call_and_report
    call = call_runtest_hook(item, when, **kwds)
           │                 │     │       └ {}
           │                 │     └ 'call'
           │                 └ <Function test_eth_chainId[data0]>
           └ <function call_runtest_hook at 0x000001D4F79A2B60>
  File "C:\Program Files\Python\Lib\site-packages\_pytest\runner.py", line 261, in call_runtest_hook
    return CallInfo.from_call(
           │        └ <classmethod(<function CallInfo.from_call at 0x000001D4F79A2DE0>)>
           └ <class '_pytest.runner.CallInfo'>
  File "C:\Program Files\Python\Lib\site-packages\_pytest\runner.py", line 341, in from_call
    result: Optional[TResult] = func()
            │        │          └ <function call_runtest_hook.<locals>.<lambda> at 0x000001D4FB904720>
            │        └ +TResult
            └ typing.Optional
  File "C:\Program Files\Python\Lib\site-packages\_pytest\runner.py", line 262, in <lambda>
    lambda: ihook(item=item, **kwds), when=when, reraise=reraise
            │          │       └ {}
            │          └ <Function test_eth_chainId[data0]>
            └ <_HookCaller 'pytest_runtest_call'>
  File "C:\Program Files\Python\Lib\site-packages\pluggy\_hooks.py", line 265, in __call__
    return self._hookexec(self.name, self.get_hookimpls(), kwargs, firstresult)
           │    │         │    │     │    │                │       └ False
           │    │         │    │     │    │                └ {'item': <Function test_eth_chainId[data0]>}
           │    │         │    │     │    └ <function _HookCaller.get_hookimpls at 0x000001D4F71D09A0>
           │    │         │    │     └ <_HookCaller 'pytest_runtest_call'>
           │    │         │    └ 'pytest_runtest_call'
           │    │         └ <_HookCaller 'pytest_runtest_call'>
           │    └ <bound method PluginManager._hookexec of <_pytest.config.PytestPluginManager object at 0x000001D4F95F9F10>>
           └ <_HookCaller 'pytest_runtest_call'>
  File "C:\Program Files\Python\Lib\site-packages\pluggy\_manager.py", line 80, in _hookexec
    return self._inner_hookexec(hook_name, methods, kwargs, firstresult)
           │    │               │          │        │       └ False
           │    │               │          │        └ {'item': <Function test_eth_chainId[data0]>}
           │    │               │          └ [<HookImpl plugin_name='runner', plugin=<module '_pytest.runner' from 'C:\\Program Files\\Python\\Lib\\site-packages\\_pytest...
           │    │               └ 'pytest_runtest_call'
           │    └ <function _multicall at 0x000001D4F71B3920>
           └ <_pytest.config.PytestPluginManager object at 0x000001D4F95F9F10>
  File "C:\Program Files\Python\Lib\site-packages\pluggy\_callers.py", line 39, in _multicall
    res = hook_impl.function(*args)
          │         │         └ [<Function test_eth_chainId[data0]>]
          │         └ <function pytest_runtest_call at 0x000001D4F79A27A0>
          └ <HookImpl plugin_name='runner', plugin=<module '_pytest.runner' from 'C:\\Program Files\\Python\\Lib\\site-packages\\_pytest\...
  File "C:\Program Files\Python\Lib\site-packages\_pytest\runner.py", line 169, in pytest_runtest_call
    item.runtest()
    │    └ <function Function.runtest at 0x000001D4F79ED6C0>
    └ <Function test_eth_chainId[data0]>
  File "C:\Program Files\Python\Lib\site-packages\_pytest\python.py", line 1799, in runtest
    self.ihook.pytest_pyfunc_call(pyfuncitem=self)
    │    │                                   └ <Function test_eth_chainId[data0]>
    │    └ <property object at 0x000001D4F74F3E20>
    └ <Function test_eth_chainId[data0]>
  File "C:\Program Files\Python\Lib\site-packages\pluggy\_hooks.py", line 265, in __call__
    return self._hookexec(self.name, self.get_hookimpls(), kwargs, firstresult)
           │    │         │    │     │    │                │       └ True
           │    │         │    │     │    │                └ {'pyfuncitem': <Function test_eth_chainId[data0]>}
           │    │         │    │     │    └ <function _HookCaller.get_hookimpls at 0x000001D4F71D09A0>
           │    │         │    │     └ <_HookCaller 'pytest_pyfunc_call'>
           │    │         │    └ 'pytest_pyfunc_call'
           │    │         └ <_HookCaller 'pytest_pyfunc_call'>
           │    └ <bound method PluginManager._hookexec of <_pytest.config.PytestPluginManager object at 0x000001D4F95F9F10>>
           └ <_HookCaller 'pytest_pyfunc_call'>
  File "C:\Program Files\Python\Lib\site-packages\pluggy\_manager.py", line 80, in _hookexec
    return self._inner_hookexec(hook_name, methods, kwargs, firstresult)
           │    │               │          │        │       └ True
           │    │               │          │        └ {'pyfuncitem': <Function test_eth_chainId[data0]>}
           │    │               │          └ [<HookImpl plugin_name='python', plugin=<module '_pytest.python' from 'C:\\Program Files\\Python\\Lib\\site-packages\\_pytest...
           │    │               └ 'pytest_pyfunc_call'
           │    └ <function _multicall at 0x000001D4F71B3920>
           └ <_pytest.config.PytestPluginManager object at 0x000001D4F95F9F10>
  File "C:\Program Files\Python\Lib\site-packages\pluggy\_callers.py", line 39, in _multicall
    res = hook_impl.function(*args)
          │         │         └ [<Function test_eth_chainId[data0]>]
          │         └ <function pytest_pyfunc_call at 0x000001D4F79C5A80>
          └ <HookImpl plugin_name='python', plugin=<module '_pytest.python' from 'C:\\Program Files\\Python\\Lib\\site-packages\\_pytest\...
  File "C:\Program Files\Python\Lib\site-packages\_pytest\python.py", line 194, in pytest_pyfunc_call
    result = testfunction(**testargs)
             │              └ {'data': {'title': '正确参数', 'payload': {'jsonrpc': '2.0', 'method': 'eth_chainId', 'params': [], 'id': 1}, 'expected': {'jsonr...
             └ <bound method TestJsonrpc.test_eth_chainId of <testcases.test_jsonrpc.TestJsonrpc object at 0x000001D4F9664950>>

  File "D:\OneDrive\Work\BlockPi\test_jsonrpc\testcases\test_jsonrpc.py", line 23, in test_eth_chainId
    result = self.eth_chainId(**data['payload'])  # 解构,等价于self.eth_chainId(jsonrpc="xxx“,method="xxxx")
             │    │             └ {'title': '正确参数', 'payload': {'jsonrpc': '2.0', 'method': 'eth_chainId', 'params': [], 'id': 1}, 'expected': {'jsonrpc': '2.0...
             │    └ <function JsonrpcApi.eth_chainId at 0x000001D4FB798D60>
             └ <testcases.test_jsonrpc.TestJsonrpc object at 0x000001D4F9664950>

  File "D:\OneDrive\Work\BlockPi\test_jsonrpc\apis\jsonrpc_api.py", line 23, in eth_chainId
    response = Utils.send_http(payload)
               │     │         └ {'url': 'http://polygon-mumbai.testnet.863863.xyz/v1/rpc/fb90c5a628b19148d4f01da617219548c978cb6e', 'method': 'post', 'header...
               │     └ <classmethod(<function Utils.send_http at 0x000001D4FB798F40>)>
               └ <class 'common.utils.Utils'>

> File "D:\OneDrive\Work\BlockPi\test_jsonrpc\common\utils.py", line 20, in send_http
    response = requests.request(**data)
               │        │         └ {'url': 'http://polygon-mumbai.testnet.863863.xyz/v1/rpc/fb90c5a628b19148d4f01da617219548c978cb6e', 'method': 'post', 'header...
               │        └ <function request at 0x000001D4FA1985E0>
               └ <module 'requests' from 'C:\\Users\\Wyc\\AppData\\Roaming\\Python\\Python311\\site-packages\\requests\\__init__.py'>

  File "C:\Users\Wyc\AppData\Roaming\Python\Python311\site-packages\requests\api.py", line 59, in request
    return session.request(method=method, url=url, **kwargs)
           │       │              │           │      └ {'headers': {'Content-Type': 'application/json'}, 'json': {'jsonrpc': '2.0', 'method': 'eth_chainId', 'params': [], 'id': 1}}
           │       │              │           └ 'http://polygon-mumbai.testnet.863863.xyz/v1/rpc/fb90c5a628b19148d4f01da617219548c978cb6e'
           │       │              └ 'post'
           │       └ <function Session.request at 0x000001D4FB9228E0>
           └ <requests.sessions.Session object at 0x000001D4FA206E10>
  File "C:\Users\Wyc\AppData\Roaming\Python\Python311\site-packages\requests\sessions.py", line 587, in request
    resp = self.send(prep, **send_kwargs)
           │    │    │       └ {'timeout': None, 'allow_redirects': True, 'proxies': OrderedDict(), 'stream': False, 'verify': True, 'cert': None}
           │    │    └ <PreparedRequest [POST]>
           │    └ <function Session.send at 0x000001D4FB922DE0>
           └ <requests.sessions.Session object at 0x000001D4FA206E10>
  File "C:\Users\Wyc\AppData\Roaming\Python\Python311\site-packages\requests\sessions.py", line 701, in send
    r = adapter.send(request, **kwargs)
        │       │    │          └ {'timeout': None, 'proxies': OrderedDict(), 'stream': False, 'verify': True, 'cert': None}
        │       │    └ <PreparedRequest [POST]>
        │       └ <function HTTPAdapter.send at 0x000001D4FB922160>
        └ <requests.adapters.HTTPAdapter object at 0x000001D4FB873C50>
  File "C:\Users\Wyc\AppData\Roaming\Python\Python311\site-packages\requests\adapters.py", line 502, in send
    raise ConnectionError(err, request=request)
          │                            └ <PreparedRequest [POST]>
          └ <class 'requests.exceptions.ConnectionError'>

requests.exceptions.ConnectionError: ('Connection aborted.', RemoteDisconnected('Remote end closed connection without response'))
2023-07-12 11:39:04.611 | INFO     | common.utils:__api_log:32 - 请求方式：post
2023-07-12 11:39:04.612 | INFO     | common.utils:__api_log:33 - 请求地址：http://polygon-mumbai.testnet.863863.xyz/v1/rpc/fb90c5a628b19148d4f01da617219548c978cb6e
2023-07-12 11:39:04.612 | INFO     | common.utils:__api_log:34 - 请求头：{'Content-Type': 'application/json'}
2023-07-12 11:39:04.612 | INFO     | common.utils:__api_log:35 - 请求参数：None
2023-07-12 11:39:04.612 | INFO     | common.utils:__api_log:36 - 请求体：{'jsonrpc': '2.0', 'method': 'eth_syncing', 'params': [], 'id': 1}

2023-07-12 11:39:04.984 | ERROR    | common.utils:send_http:23 - 发送请求失败，请求参数为：{'url': 'http://polygon-mumbai.testnet.863863.xyz/v1/rpc/fb90c5a628b19148d4f01da617219548c978cb6e', 'method': 'post', 'headers': {'Content-Type': 'application/json'}, 'json': {'jsonrpc': '2.0', 'method': 'eth_syncing', 'params': [], 'id': 1}}
2023-07-12 11:39:04.984 | ERROR    | common.utils:send_http:24 - 发生的错误为：('Connection aborted.', RemoteDisconnected('Remote end closed connection without response'))
Traceback (most recent call last):

  File "C:\Users\Wyc\AppData\Roaming\Python\Python311\site-packages\urllib3\connectionpool.py", line 703, in urlopen
    httplib_response = self._make_request(
                       │    └ <function HTTPConnectionPool._make_request at 0x000001D4FCD5B380>
                       └ <urllib3.connectionpool.HTTPConnectionPool object at 0x000001D4FCEC0910>
  File "C:\Users\Wyc\AppData\Roaming\Python\Python311\site-packages\urllib3\connectionpool.py", line 449, in _make_request
    six.raise_from(e, None)
    │   └ <function raise_from at 0x000001D4FB79B740>
    └ <module 'urllib3.packages.six' from 'C:\\Users\\Wyc\\AppData\\Roaming\\Python\\Python311\\site-packages\\urllib3\\packages\\s...
  File "<string>", line 3, in raise_from
  File "C:\Users\Wyc\AppData\Roaming\Python\Python311\site-packages\urllib3\connectionpool.py", line 444, in _make_request
    httplib_response = conn.getresponse()
                       │    └ <function HTTPConnection.getresponse at 0x000001D4FB7F6340>
                       └ <urllib3.connection.HTTPConnection object at 0x000001D4FCEC1B10>
  File "C:\Program Files\Python\Lib\http\client.py", line 1375, in getresponse
    response.begin()
    │        └ <function HTTPResponse.begin at 0x000001D4FB7F4400>
    └ <http.client.HTTPResponse object at 0x000001D4FB8EA7A0>
  File "C:\Program Files\Python\Lib\http\client.py", line 318, in begin
    version, status, reason = self._read_status()
                              │    └ <function HTTPResponse._read_status at 0x000001D4FB7F4360>
                              └ <http.client.HTTPResponse object at 0x000001D4FB8EA7A0>
  File "C:\Program Files\Python\Lib\http\client.py", line 287, in _read_status
    raise RemoteDisconnected("Remote end closed connection without"
          └ <class 'http.client.RemoteDisconnected'>

http.client.RemoteDisconnected: Remote end closed connection without response


During handling of the above exception, another exception occurred:


Traceback (most recent call last):

  File "C:\Users\Wyc\AppData\Roaming\Python\Python311\site-packages\requests\adapters.py", line 487, in send
    resp = conn.urlopen(
           │    └ <function HTTPConnectionPool.urlopen at 0x000001D4FCD5B600>
           └ <urllib3.connectionpool.HTTPConnectionPool object at 0x000001D4FCEC0910>
  File "C:\Users\Wyc\AppData\Roaming\Python\Python311\site-packages\urllib3\connectionpool.py", line 787, in urlopen
    retries = retries.increment(
              │       └ <function Retry.increment at 0x000001D4FB813600>
              └ Retry(total=0, connect=None, read=False, redirect=None, status=None)
  File "C:\Users\Wyc\AppData\Roaming\Python\Python311\site-packages\urllib3\util\retry.py", line 550, in increment
    raise six.reraise(type(error), error, _stacktrace)
          │   │            │       │      └ <traceback object at 0x000001D4FCEC1CC0>
          │   │            │       └ ProtocolError('Connection aborted.', RemoteDisconnected('Remote end closed connection without response'))
          │   │            └ ProtocolError('Connection aborted.', RemoteDisconnected('Remote end closed connection without response'))
          │   └ <function reraise at 0x000001D4FB79B600>
          └ <module 'urllib3.packages.six' from 'C:\\Users\\Wyc\\AppData\\Roaming\\Python\\Python311\\site-packages\\urllib3\\packages\\s...
  File "C:\Users\Wyc\AppData\Roaming\Python\Python311\site-packages\urllib3\packages\six.py", line 769, in reraise
    raise value.with_traceback(tb)
          │                    └ None
          └ None
  File "C:\Users\Wyc\AppData\Roaming\Python\Python311\site-packages\urllib3\connectionpool.py", line 703, in urlopen
    httplib_response = self._make_request(
                       │    └ <function HTTPConnectionPool._make_request at 0x000001D4FCD5B380>
                       └ <urllib3.connectionpool.HTTPConnectionPool object at 0x000001D4FCEC0910>
  File "C:\Users\Wyc\AppData\Roaming\Python\Python311\site-packages\urllib3\connectionpool.py", line 449, in _make_request
    six.raise_from(e, None)
    │   └ <function raise_from at 0x000001D4FB79B740>
    └ <module 'urllib3.packages.six' from 'C:\\Users\\Wyc\\AppData\\Roaming\\Python\\Python311\\site-packages\\urllib3\\packages\\s...
  File "<string>", line 3, in raise_from
  File "C:\Users\Wyc\AppData\Roaming\Python\Python311\site-packages\urllib3\connectionpool.py", line 444, in _make_request
    httplib_response = conn.getresponse()
                       │    └ <function HTTPConnection.getresponse at 0x000001D4FB7F6340>
                       └ <urllib3.connection.HTTPConnection object at 0x000001D4FCEC1B10>
  File "C:\Program Files\Python\Lib\http\client.py", line 1375, in getresponse
    response.begin()
    │        └ <function HTTPResponse.begin at 0x000001D4FB7F4400>
    └ <http.client.HTTPResponse object at 0x000001D4FB8EA7A0>
  File "C:\Program Files\Python\Lib\http\client.py", line 318, in begin
    version, status, reason = self._read_status()
                              │    └ <function HTTPResponse._read_status at 0x000001D4FB7F4360>
                              └ <http.client.HTTPResponse object at 0x000001D4FB8EA7A0>
  File "C:\Program Files\Python\Lib\http\client.py", line 287, in _read_status
    raise RemoteDisconnected("Remote end closed connection without"
          └ <class 'http.client.RemoteDisconnected'>

urllib3.exceptions.ProtocolError: ('Connection aborted.', RemoteDisconnected('Remote end closed connection without response'))


During handling of the above exception, another exception occurred:


Traceback (most recent call last):

  File "D:\OneDrive\Work\BlockPi\test_jsonrpc\run.py", line 11, in <module>
    pytest.main(['-s', r"--alluredir=report/json", "--clean-alluredir"])
    │      └ <function main at 0x000001D4F74F5260>
    └ <module 'pytest' from 'C:\\Program Files\\Python\\Lib\\site-packages\\pytest\\__init__.py'>

  File "C:\Program Files\Python\Lib\site-packages\_pytest\config\__init__.py", line 166, in main
    ret: Union[ExitCode, int] = config.hook.pytest_cmdline_main(
         │     │                │      │    └ <_HookCaller 'pytest_cmdline_main'>
         │     │                │      └ <_pytest.config.compat.PathAwareHookProxy object at 0x000001D4F960E4D0>
         │     │                └ <_pytest.config.Config object at 0x000001D4F95FADD0>
         │     └ <enum 'ExitCode'>
         └ typing.Union
  File "C:\Program Files\Python\Lib\site-packages\pluggy\_hooks.py", line 265, in __call__
    return self._hookexec(self.name, self.get_hookimpls(), kwargs, firstresult)
           │    │         │    │     │    │                │       └ True
           │    │         │    │     │    │                └ {'config': <_pytest.config.Config object at 0x000001D4F95FADD0>}
           │    │         │    │     │    └ <function _HookCaller.get_hookimpls at 0x000001D4F71D09A0>
           │    │         │    │     └ <_HookCaller 'pytest_cmdline_main'>
           │    │         │    └ 'pytest_cmdline_main'
           │    │         └ <_HookCaller 'pytest_cmdline_main'>
           │    └ <bound method PluginManager._hookexec of <_pytest.config.PytestPluginManager object at 0x000001D4F95F9F10>>
           └ <_HookCaller 'pytest_cmdline_main'>
  File "C:\Program Files\Python\Lib\site-packages\pluggy\_manager.py", line 80, in _hookexec
    return self._inner_hookexec(hook_name, methods, kwargs, firstresult)
           │    │               │          │        │       └ True
           │    │               │          │        └ {'config': <_pytest.config.Config object at 0x000001D4F95FADD0>}
           │    │               │          └ [<HookImpl plugin_name='main', plugin=<module '_pytest.main' from 'C:\\Program Files\\Python\\Lib\\site-packages\\_pytest\\ma...
           │    │               └ 'pytest_cmdline_main'
           │    └ <function _multicall at 0x000001D4F71B3920>
           └ <_pytest.config.PytestPluginManager object at 0x000001D4F95F9F10>
  File "C:\Program Files\Python\Lib\site-packages\pluggy\_callers.py", line 39, in _multicall
    res = hook_impl.function(*args)
          │         │         └ [<_pytest.config.Config object at 0x000001D4F95FADD0>]
          │         └ <function pytest_cmdline_main at 0x000001D4F79A3560>
          └ <HookImpl plugin_name='main', plugin=<module '_pytest.main' from 'C:\\Program Files\\Python\\Lib\\site-packages\\_pytest\\mai...
  File "C:\Program Files\Python\Lib\site-packages\_pytest\main.py", line 316, in pytest_cmdline_main
    return wrap_session(config, _main)
           │            │       └ <function _main at 0x000001D4F79A34C0>
           │            └ <_pytest.config.Config object at 0x000001D4F95FADD0>
           └ <function wrap_session at 0x000001D4F79A3420>
  File "C:\Program Files\Python\Lib\site-packages\_pytest\main.py", line 269, in wrap_session
    session.exitstatus = doit(config, session) or 0
    │       │            │    │       └ <Session test_jsonrpc exitstatus=<ExitCode.OK: 0> testsfailed=1 testscollected=3>
    │       │            │    └ <_pytest.config.Config object at 0x000001D4F95FADD0>
    │       │            └ <function _main at 0x000001D4F79A34C0>
    │       └ <ExitCode.OK: 0>
    └ <Session test_jsonrpc exitstatus=<ExitCode.OK: 0> testsfailed=1 testscollected=3>
  File "C:\Program Files\Python\Lib\site-packages\_pytest\main.py", line 323, in _main
    config.hook.pytest_runtestloop(session=session)
    │      │    │                          └ <Session test_jsonrpc exitstatus=<ExitCode.OK: 0> testsfailed=1 testscollected=3>
    │      │    └ <_HookCaller 'pytest_runtestloop'>
    │      └ <_pytest.config.compat.PathAwareHookProxy object at 0x000001D4F960E4D0>
    └ <_pytest.config.Config object at 0x000001D4F95FADD0>
  File "C:\Program Files\Python\Lib\site-packages\pluggy\_hooks.py", line 265, in __call__
    return self._hookexec(self.name, self.get_hookimpls(), kwargs, firstresult)
           │    │         │    │     │    │                │       └ True
           │    │         │    │     │    │                └ {'session': <Session test_jsonrpc exitstatus=<ExitCode.OK: 0> testsfailed=1 testscollected=3>}
           │    │         │    │     │    └ <function _HookCaller.get_hookimpls at 0x000001D4F71D09A0>
           │    │         │    │     └ <_HookCaller 'pytest_runtestloop'>
           │    │         │    └ 'pytest_runtestloop'
           │    │         └ <_HookCaller 'pytest_runtestloop'>
           │    └ <bound method PluginManager._hookexec of <_pytest.config.PytestPluginManager object at 0x000001D4F95F9F10>>
           └ <_HookCaller 'pytest_runtestloop'>
  File "C:\Program Files\Python\Lib\site-packages\pluggy\_manager.py", line 80, in _hookexec
    return self._inner_hookexec(hook_name, methods, kwargs, firstresult)
           │    │               │          │        │       └ True
           │    │               │          │        └ {'session': <Session test_jsonrpc exitstatus=<ExitCode.OK: 0> testsfailed=1 testscollected=3>}
           │    │               │          └ [<HookImpl plugin_name='main', plugin=<module '_pytest.main' from 'C:\\Program Files\\Python\\Lib\\site-packages\\_pytest\\ma...
           │    │               └ 'pytest_runtestloop'
           │    └ <function _multicall at 0x000001D4F71B3920>
           └ <_pytest.config.PytestPluginManager object at 0x000001D4F95F9F10>
  File "C:\Program Files\Python\Lib\site-packages\pluggy\_callers.py", line 39, in _multicall
    res = hook_impl.function(*args)
          │         │         └ [<Session test_jsonrpc exitstatus=<ExitCode.OK: 0> testsfailed=1 testscollected=3>]
          │         └ <function pytest_runtestloop at 0x000001D4F79A36A0>
          └ <HookImpl plugin_name='main', plugin=<module '_pytest.main' from 'C:\\Program Files\\Python\\Lib\\site-packages\\_pytest\\mai...
  File "C:\Program Files\Python\Lib\site-packages\_pytest\main.py", line 348, in pytest_runtestloop
    item.config.hook.pytest_runtest_protocol(item=item, nextitem=nextitem)
    │    │                                        │              └ <Function test_eth_getBlockByNumber>
    │    │                                        └ <Function test_eth_syncing[data0]>
    │    └ <member 'config' of 'Node' objects>
    └ <Function test_eth_syncing[data0]>
  File "C:\Program Files\Python\Lib\site-packages\pluggy\_hooks.py", line 265, in __call__
    return self._hookexec(self.name, self.get_hookimpls(), kwargs, firstresult)
           │    │         │    │     │    │                │       └ True
           │    │         │    │     │    │                └ {'item': <Function test_eth_syncing[data0]>, 'nextitem': <Function test_eth_getBlockByNumber>}
           │    │         │    │     │    └ <function _HookCaller.get_hookimpls at 0x000001D4F71D09A0>
           │    │         │    │     └ <_HookCaller 'pytest_runtest_protocol'>
           │    │         │    └ 'pytest_runtest_protocol'
           │    │         └ <_HookCaller 'pytest_runtest_protocol'>
           │    └ <bound method PluginManager._hookexec of <_pytest.config.PytestPluginManager object at 0x000001D4F95F9F10>>
           └ <_HookCaller 'pytest_runtest_protocol'>
  File "C:\Program Files\Python\Lib\site-packages\pluggy\_manager.py", line 80, in _hookexec
    return self._inner_hookexec(hook_name, methods, kwargs, firstresult)
           │    │               │          │        │       └ True
           │    │               │          │        └ {'item': <Function test_eth_syncing[data0]>, 'nextitem': <Function test_eth_getBlockByNumber>}
           │    │               │          └ [<HookImpl plugin_name='runner', plugin=<module '_pytest.runner' from 'C:\\Program Files\\Python\\Lib\\site-packages\\_pytest...
           │    │               └ 'pytest_runtest_protocol'
           │    └ <function _multicall at 0x000001D4F71B3920>
           └ <_pytest.config.PytestPluginManager object at 0x000001D4F95F9F10>
  File "C:\Program Files\Python\Lib\site-packages\pluggy\_callers.py", line 39, in _multicall
    res = hook_impl.function(*args)
          │         │         └ [<Function test_eth_syncing[data0]>, <Function test_eth_getBlockByNumber>]
          │         └ <function pytest_runtest_protocol at 0x000001D4F79A2520>
          └ <HookImpl plugin_name='runner', plugin=<module '_pytest.runner' from 'C:\\Program Files\\Python\\Lib\\site-packages\\_pytest\...
  File "C:\Program Files\Python\Lib\site-packages\_pytest\runner.py", line 114, in pytest_runtest_protocol
    runtestprotocol(item, nextitem=nextitem)
    │               │              └ <Function test_eth_getBlockByNumber>
    │               └ <Function test_eth_syncing[data0]>
    └ <function runtestprotocol at 0x000001D4F79A25C0>
  File "C:\Program Files\Python\Lib\site-packages\_pytest\runner.py", line 133, in runtestprotocol
    reports.append(call_and_report(item, "call", log))
    │       │      │               │             └ True
    │       │      │               └ <Function test_eth_syncing[data0]>
    │       │      └ <function call_and_report at 0x000001D4F79A2980>
    │       └ <method 'append' of 'list' objects>
    └ [<TestReport 'testcases/test_jsonrpc.py::TestJsonrpc::test_eth_syncing[data0]' when='setup' outcome='passed'>]
  File "C:\Program Files\Python\Lib\site-packages\_pytest\runner.py", line 222, in call_and_report
    call = call_runtest_hook(item, when, **kwds)
           │                 │     │       └ {}
           │                 │     └ 'call'
           │                 └ <Function test_eth_syncing[data0]>
           └ <function call_runtest_hook at 0x000001D4F79A2B60>
  File "C:\Program Files\Python\Lib\site-packages\_pytest\runner.py", line 261, in call_runtest_hook
    return CallInfo.from_call(
           │        └ <classmethod(<function CallInfo.from_call at 0x000001D4F79A2DE0>)>
           └ <class '_pytest.runner.CallInfo'>
  File "C:\Program Files\Python\Lib\site-packages\_pytest\runner.py", line 341, in from_call
    result: Optional[TResult] = func()
            │        │          └ <function call_runtest_hook.<locals>.<lambda> at 0x000001D4FB907380>
            │        └ +TResult
            └ typing.Optional
  File "C:\Program Files\Python\Lib\site-packages\_pytest\runner.py", line 262, in <lambda>
    lambda: ihook(item=item, **kwds), when=when, reraise=reraise
            │          │       └ {}
            │          └ <Function test_eth_syncing[data0]>
            └ <_HookCaller 'pytest_runtest_call'>
  File "C:\Program Files\Python\Lib\site-packages\pluggy\_hooks.py", line 265, in __call__
    return self._hookexec(self.name, self.get_hookimpls(), kwargs, firstresult)
           │    │         │    │     │    │                │       └ False
           │    │         │    │     │    │                └ {'item': <Function test_eth_syncing[data0]>}
           │    │         │    │     │    └ <function _HookCaller.get_hookimpls at 0x000001D4F71D09A0>
           │    │         │    │     └ <_HookCaller 'pytest_runtest_call'>
           │    │         │    └ 'pytest_runtest_call'
           │    │         └ <_HookCaller 'pytest_runtest_call'>
           │    └ <bound method PluginManager._hookexec of <_pytest.config.PytestPluginManager object at 0x000001D4F95F9F10>>
           └ <_HookCaller 'pytest_runtest_call'>
  File "C:\Program Files\Python\Lib\site-packages\pluggy\_manager.py", line 80, in _hookexec
    return self._inner_hookexec(hook_name, methods, kwargs, firstresult)
           │    │               │          │        │       └ False
           │    │               │          │        └ {'item': <Function test_eth_syncing[data0]>}
           │    │               │          └ [<HookImpl plugin_name='runner', plugin=<module '_pytest.runner' from 'C:\\Program Files\\Python\\Lib\\site-packages\\_pytest...
           │    │               └ 'pytest_runtest_call'
           │    └ <function _multicall at 0x000001D4F71B3920>
           └ <_pytest.config.PytestPluginManager object at 0x000001D4F95F9F10>
  File "C:\Program Files\Python\Lib\site-packages\pluggy\_callers.py", line 39, in _multicall
    res = hook_impl.function(*args)
          │         │         └ [<Function test_eth_syncing[data0]>]
          │         └ <function pytest_runtest_call at 0x000001D4F79A27A0>
          └ <HookImpl plugin_name='runner', plugin=<module '_pytest.runner' from 'C:\\Program Files\\Python\\Lib\\site-packages\\_pytest\...
  File "C:\Program Files\Python\Lib\site-packages\_pytest\runner.py", line 169, in pytest_runtest_call
    item.runtest()
    │    └ <function Function.runtest at 0x000001D4F79ED6C0>
    └ <Function test_eth_syncing[data0]>
  File "C:\Program Files\Python\Lib\site-packages\_pytest\python.py", line 1799, in runtest
    self.ihook.pytest_pyfunc_call(pyfuncitem=self)
    │    │                                   └ <Function test_eth_syncing[data0]>
    │    └ <property object at 0x000001D4F74F3E20>
    └ <Function test_eth_syncing[data0]>
  File "C:\Program Files\Python\Lib\site-packages\pluggy\_hooks.py", line 265, in __call__
    return self._hookexec(self.name, self.get_hookimpls(), kwargs, firstresult)
           │    │         │    │     │    │                │       └ True
           │    │         │    │     │    │                └ {'pyfuncitem': <Function test_eth_syncing[data0]>}
           │    │         │    │     │    └ <function _HookCaller.get_hookimpls at 0x000001D4F71D09A0>
           │    │         │    │     └ <_HookCaller 'pytest_pyfunc_call'>
           │    │         │    └ 'pytest_pyfunc_call'
           │    │         └ <_HookCaller 'pytest_pyfunc_call'>
           │    └ <bound method PluginManager._hookexec of <_pytest.config.PytestPluginManager object at 0x000001D4F95F9F10>>
           └ <_HookCaller 'pytest_pyfunc_call'>
  File "C:\Program Files\Python\Lib\site-packages\pluggy\_manager.py", line 80, in _hookexec
    return self._inner_hookexec(hook_name, methods, kwargs, firstresult)
           │    │               │          │        │       └ True
           │    │               │          │        └ {'pyfuncitem': <Function test_eth_syncing[data0]>}
           │    │               │          └ [<HookImpl plugin_name='python', plugin=<module '_pytest.python' from 'C:\\Program Files\\Python\\Lib\\site-packages\\_pytest...
           │    │               └ 'pytest_pyfunc_call'
           │    └ <function _multicall at 0x000001D4F71B3920>
           └ <_pytest.config.PytestPluginManager object at 0x000001D4F95F9F10>
  File "C:\Program Files\Python\Lib\site-packages\pluggy\_callers.py", line 39, in _multicall
    res = hook_impl.function(*args)
          │         │         └ [<Function test_eth_syncing[data0]>]
          │         └ <function pytest_pyfunc_call at 0x000001D4F79C5A80>
          └ <HookImpl plugin_name='python', plugin=<module '_pytest.python' from 'C:\\Program Files\\Python\\Lib\\site-packages\\_pytest\...
  File "C:\Program Files\Python\Lib\site-packages\_pytest\python.py", line 194, in pytest_pyfunc_call
    result = testfunction(**testargs)
             │              └ {'data': {'title': '正确参数', 'payload': {'jsonrpc': '2.0', 'method': 'eth_syncing', 'params': [], 'id': 1}, 'expected': {'jsonr...
             └ <bound method TestJsonrpc.test_eth_syncing of <testcases.test_jsonrpc.TestJsonrpc object at 0x000001D4F96B9B50>>

  File "D:\OneDrive\Work\BlockPi\test_jsonrpc\testcases\test_jsonrpc.py", line 32, in test_eth_syncing
    result = self.eth_syncing(**data['payload'])
             │    │             └ {'title': '正确参数', 'payload': {'jsonrpc': '2.0', 'method': 'eth_syncing', 'params': [], 'id': 1}, 'expected': {'jsonrpc': '2.0...
             │    └ <function JsonrpcApi.eth_syncing at 0x000001D4FB763380>
             └ <testcases.test_jsonrpc.TestJsonrpc object at 0x000001D4F96B9B50>

  File "D:\OneDrive\Work\BlockPi\test_jsonrpc\apis\jsonrpc_api.py", line 34, in eth_syncing
    response = Utils.send_http(payload)
               │     │         └ {'url': 'http://polygon-mumbai.testnet.863863.xyz/v1/rpc/fb90c5a628b19148d4f01da617219548c978cb6e', 'method': 'post', 'header...
               │     └ <classmethod(<function Utils.send_http at 0x000001D4FB798F40>)>
               └ <class 'common.utils.Utils'>

> File "D:\OneDrive\Work\BlockPi\test_jsonrpc\common\utils.py", line 20, in send_http
    response = requests.request(**data)
               │        │         └ {'url': 'http://polygon-mumbai.testnet.863863.xyz/v1/rpc/fb90c5a628b19148d4f01da617219548c978cb6e', 'method': 'post', 'header...
               │        └ <function request at 0x000001D4FA1985E0>
               └ <module 'requests' from 'C:\\Users\\Wyc\\AppData\\Roaming\\Python\\Python311\\site-packages\\requests\\__init__.py'>

  File "C:\Users\Wyc\AppData\Roaming\Python\Python311\site-packages\requests\api.py", line 59, in request
    return session.request(method=method, url=url, **kwargs)
           │       │              │           │      └ {'headers': {'Content-Type': 'application/json'}, 'json': {'jsonrpc': '2.0', 'method': 'eth_syncing', 'params': [], 'id': 1}}
           │       │              │           └ 'http://polygon-mumbai.testnet.863863.xyz/v1/rpc/fb90c5a628b19148d4f01da617219548c978cb6e'
           │       │              └ 'post'
           │       └ <function Session.request at 0x000001D4FB9228E0>
           └ <requests.sessions.Session object at 0x000001D4FB8A1450>
  File "C:\Users\Wyc\AppData\Roaming\Python\Python311\site-packages\requests\sessions.py", line 587, in request
    resp = self.send(prep, **send_kwargs)
           │    │    │       └ {'timeout': None, 'allow_redirects': True, 'proxies': OrderedDict(), 'stream': False, 'verify': True, 'cert': None}
           │    │    └ <PreparedRequest [POST]>
           │    └ <function Session.send at 0x000001D4FB922DE0>
           └ <requests.sessions.Session object at 0x000001D4FB8A1450>
  File "C:\Users\Wyc\AppData\Roaming\Python\Python311\site-packages\requests\sessions.py", line 701, in send
    r = adapter.send(request, **kwargs)
        │       │    │          └ {'timeout': None, 'proxies': OrderedDict(), 'stream': False, 'verify': True, 'cert': None}
        │       │    └ <PreparedRequest [POST]>
        │       └ <function HTTPAdapter.send at 0x000001D4FB922160>
        └ <requests.adapters.HTTPAdapter object at 0x000001D4FCEC0A90>
  File "C:\Users\Wyc\AppData\Roaming\Python\Python311\site-packages\requests\adapters.py", line 502, in send
    raise ConnectionError(err, request=request)
          │                            └ <PreparedRequest [POST]>
          └ <class 'requests.exceptions.ConnectionError'>

requests.exceptions.ConnectionError: ('Connection aborted.', RemoteDisconnected('Remote end closed connection without response'))
